<mujoco model="bruce_op">
    <compiler angle="radian" meshdir="meshes" autolimits="false" inertiafromgeom="false"/>
	
    <option timestep="0.001" gravity="0 0 -9.81" tolerance="1e-05" cone="elliptic" jacobian="dense" solver="Newton"  noslip_iterations="10" integrator="Euler" iterations="30" impratio="10.0"/> 
    <option>
      <flag override="enable" gravity="enable"/>
    </option>

    <asset>
        <mesh name="base_link" file="base_link.STL"/>
        <mesh name="ankle_pitch_link_l" file="ankle_pitch_link_l.stl"/>
        <mesh name="ankle_pitch_link_r" file="ankle_pitch_link_r.stl"/>
        <mesh name="elbow_pitch_link_l" file="elbow_pitch_link_l.stl"/>
        <mesh name="elbow_pitch_link_r" file="elbow_pitch_link_r.stl"/>
        <mesh name="hip_pitch_link_l" file="hip_pitch_link_l.stl"/>
        <mesh name="hip_pitch_link_r" file="hip_pitch_link_r.stl"/>
        <mesh name="hip_roll_link_l" file="hip_roll_link_l.stl"/>
        <mesh name="hip_roll_link_r" file="hip_roll_link_r.stl"/>
        <mesh name="hip_yaw_link_l" file="hip_yaw_link_l.stl"/>
        <mesh name="hip_yaw_link_r" file="hip_yaw_link_r.stl"/>
        <mesh name="knee_pitch_link_l" file="knee_pitch_link_l.stl"/>
        <mesh name="knee_pitch_link_r" file="knee_pitch_link_r.stl"/>
        <mesh name="shoulder_pitch_link_l" file="shoulder_pitch_link_l.stl"/>
        <mesh name="shoulder_pitch_link_r" file="shoulder_pitch_link_r.stl"/>
        <mesh name="shoulder_roll_link_l" file="shoulder_roll_link_l.stl"/>
        <mesh name="shoulder_roll_link_r" file="shoulder_roll_link_r.stl"/>
        
        <texture name="texplane" type="2d" builtin="checker" width="512" height="512" rgb1="0.1 0.2 0.3" rgb2="0.5 0.6 0.7" mark="edge" markrgb="1 1 1" />
		    <material name="MatLink"  reflectance="0.5" specular="1" shininess="0.3" rgba="0.5 0.5 0.5 1"/>
        <material name="MatPlane" texture="texplane" reflectance="0" texrepeat="1 1" texuniform="true"/>
    </asset>

    <default>
      <!-- <geom contype="1" conaffinity="1" condim="3" material="MatLink"/> -->
      <joint limited="false" damping="2" armature="0.1" stiffness="0" frictionloss="0.2"/>
      <!-- <joint limited="false" damping="0.5" armature="0.1" stiffness="0" frictionloss="0.2"/> -->
      <motor gear="1 0 0 0 0 0" ctrllimited="false" ctrlrange="-100 100"/>
    </default>

    <!-- Ref:https://github.com/google-deepmind/mujoco_menagerie/blob/main/robotis_op3/op3.xml -->
    <!-- <default>
      <mesh scale="0.001 0.001 0.001"/>
      <geom type="mesh" solref=".004 1"/>
      <joint damping="1.084" armature="0.045" frictionloss="0.03"/>
      <site group="5" type="sphere"/>
      <position kp="21.1" ctrlrange="-3.141592 3.141592" forcerange="-5 5"/>
      <default class="collision">
        <geom group="3"/>
        <default class="foot">
          <geom mass="0" type="box"/>
        </default>
      </default>
      <default class="visual">
        <geom material="black" contype="0" conaffinity="0" group="2"/>
      </default>
    </default> -->

    <visual>
      <global fovy="45" linewidth="2" glow="0.3"/>
      <quality shadowsize="4096" numslices="48"/>
      <map stiffness="50" stiffnessrot="100"/>
      <scale forcewidth="0.075" contactwidth="0.2" contactheight="0.1" connect="0.1" com="0.2" jointlength="0.25" jointwidth="0.05"
             actuatorlength="0.5" actuatorwidth="0.3" framelength="1" framewidth="0.03"/>
      <rgba haze="0.6 0.8 0.9 1" force="1 0 0 0.5" com="0 0 1 1"/>
    </visual>

    <worldbody>
        <light name="spotlight" mode="targetbodycom" target="body_link" pos="10 -10 10" diffuse="1.0 1.0 1.0" specular="0.0 0.0 0.0" castshadow="false"/>

		    <geom name="Ground" type="plane" pos="0 0 0" material="MatPlane" size="0 0 1" condim="3"/>
        
        <body name="body_link" pos="0 0 0.47">
    		<freejoint/>
            <inertial pos="0.02259605 -0.00011305 0.06140054" mass="1.31688922" diaginertia="0.0133543 0.01023631 0.005471"/>
            <geom name="base_link" type="mesh" mesh="base_link" rgba="0.752941176 0.752941176 0.752941176 1"/>

            <!-- LEFT LEG -->
            <body name="hip_yaw_link_l" pos="0.029216 0.0758557 -0.039765" quat="0.707107 0 0 -0.707107">
                <inertial pos="0 -0.00020849 0.00528032" quat="0.518836 0.480432 0.518756 0.480506" mass="0.637386" diaginertia="0.00161868 0.00152047 0.0004852"/>
                <joint name="hip_yaw_l" pos="0 0 0" axis="0 0 1" limited="true" range="-0.785375 0.785375"/>
                <geom type="mesh" rgba="0.752941 0.752941 0.752941 1" mesh="hip_yaw_link_l" contype="0" conaffinity="0"/>
                <body name="hip_roll_link_l" quat="0.500001 -0.499999 0.500001 0.499999">
                  <inertial pos="-1.51e-07 0 6.88e-06" mass="0.05" diaginertia="1e-05 1e-05 1e-05"/>
                  <joint name="hip_roll_l" pos="0 0 0" axis="0 0 1" limited="true" range="-0.785375 0.785375"/>
                  <geom type="mesh" rgba="0.752941 0.752941 0.752941 1" mesh="hip_roll_link_l" contype="0" conaffinity="0"/>
                  <body name="hip_pitch_link_l" quat="0.707107 0.707107 0 0">
                    <inertial pos="0.142447 -0.00832054 0.00049317" quat="-0.002203 0.702817 0.024599 0.710942" mass="0.720628" diaginertia="0.018195 0.0179541 0.000461885"/>
                    <joint name="hip_pitch_l" pos="0 0 0" axis="0 0 1" limited="true" range="-1.57075 1.57075"/>
                    <geom type="mesh" rgba="0.752941 0.752941 0.752941 1" mesh="hip_pitch_link_l"/>
                    <body name="knee_pitch_link_l" pos="0.204949 0 0">
                      <inertial pos="0.0730996 0.0178102 -0.00219767" quat="0.0505999 0.70058 0.00930476 0.711716" mass="0.0952654" diaginertia="0.00107995 0.00101966 0.000104635"/>
                      <joint name="knee_pitch_l" pos="0 0 0" axis="0 0 1" limited="true" range="-1.57075 1.57075"/>
                      <geom type="mesh" rgba="0.752941 0.752941 0.752941 1" mesh="knee_pitch_link_l"/>
                      <body name="ankle_pitch_link_l" pos="0.199881 0 0">
                        <inertial pos="0.0123398 0.00253004 -0.00030441" quat="0.455603 0.546571 -0.442281 0.545962" mass="0.0274829" diaginertia="2.60237e-05 2.09939e-05 5.69233e-06"/>
                        <joint name="ankle_pitch_l" pos="0 0 0" axis="0 0 1" limited="true" range="-1.57075 1.57075"/>
                        <geom type="mesh" rgba="0.792157 0.819608 0.933333 1" mesh="ankle_pitch_link_l"/>
        								<site name="lfoot_sensor" type="sphere" pos="0 0 0" size="0.005" rgba="1 0 0 1"/>
                      </body>
                    </body>
                  </body>
                </body>
              </body>

            <!-- RIGHT LEG -->
            <body name="hip_yaw_link_r" pos="0.029216 -0.0758557 -0.039765" quat="0.707107 0 0 -0.707107">
                <inertial pos="2.71e-06 -0.00024824 0.00522427" quat="0.517691 0.482114 0.518083 0.480784" mass="0.637563" diaginertia="0.0016174 0.00152078 0.000485406"/>
                <joint name="hip_yaw_r" pos="0 0 0" axis="0 0 1" limited="true" range="-0.785375 0.785375"/>
                <geom type="mesh" rgba="0.752941 0.752941 0.752941 1" mesh="hip_yaw_link_r" contype="0" conaffinity="0"/>
                <body name="hip_roll_link_r" quat="0.5 -0.5 0.5 0.5">
                  <inertial pos="-1.51e-07 0 6.88e-06" mass="0.05" diaginertia="1e-05 1e-05 1e-05"/>
                  <joint name="hip_roll_r" pos="0 0 0" axis="0 0 1" limited="true" range="-0.785375 0.785375"/>
                  <geom type="mesh" rgba="0.752941 0.752941 0.752941 1" mesh="hip_roll_link_r" contype="0" conaffinity="0"/>
                  <body name="hip_pitch_link_r" quat="0.707107 0.707107 0 0">
                    <inertial pos="0.140714 -0.0086817 0.00167429" quat="-0.0210718 0.710934 0.00543456 0.702922" mass="0.72849" diaginertia="0.0181996 0.0179488 0.000479326"/>
                    <joint name="hip_pitch_r" pos="0 0 0" axis="0 0 1" limited="true" range="-1.57075 1.57075"/>
                    <geom type="mesh" rgba="0.752941 0.752941 0.752941 1" mesh="hip_pitch_link_r"/>
                    <body name="knee_pitch_link_r" pos="0.204949 0 0">
                      <inertial pos="0.0729308 0.0174645 0.00216432" quat="-0.0124752 0.71085 -0.0538621 0.701167" mass="0.0956654" diaginertia="0.00108397 0.00102192 0.000106307"/>
                      <joint name="knee_pitch_r" pos="0 0 0" axis="0 0 1" limited="true" range="-1.57075 1.57075"/>
                      <geom type="mesh" rgba="0.752941 0.752941 0.752941 1" mesh="knee_pitch_link_r"/>
                      <body name="ankle_pitch_link_r" pos="0.199881 0 0">
                        <inertial pos="0.0120775 0.0019746 0.00029511" quat="0.443128 0.545146 -0.456612 0.545855" mass="0.0276265" diaginertia="2.58838e-05 2.09859e-05 5.64035e-06"/>
                        <joint name="ankle_pitch_r" pos="0 0 0" axis="0 0 1" limited="true" range="-1.57075 1.57075"/>
                        <geom type="mesh" rgba="0.792157 0.819608 0.933333 1" mesh="ankle_pitch_link_r"/>
        								<site name="rfoot_sensor" type="sphere" pos="0 0 0" size="0.005" rgba="1 0 0 1"/>
                      </body>
                    </body>
                  </body>
                </body>
              </body>

              <!-- LEFT ARM -->
            <body name="shoulder_pitch_link_l" pos="0.029216 0.12375 0.152985" quat="0.5 -0.5 0.5 0.5">
              <inertial pos="0 0.00038323 -0.0141368" quat="0.999984 -0.0057278 0 0" mass="0.0493169" diaginertia="2.507e-05 2.40321e-05 8.31794e-06"/>
              <joint name="shoulder_pitch_l" pos="0 0 0" axis="0 0 1" limited="true" range="-1.57075 1.57075"/>
              <geom type="mesh" rgba="0.752941 0.752941 0.752941 1" mesh="shoulder_pitch_link_l"/>
              <body name="shoulder_roll_link_l" quat="0.5 0.5 -0.5 0.5">
                <inertial pos="0.0570939 0.00419463 0.00094155" quat="0.207025 0.693936 0.171489 0.667971" mass="0.0313652" diaginertia="0.000165195 0.000164406 9.52871e-06"/>
                <joint name="shoulder_roll_l" pos="0 0 0" axis="0 0 1" limited="true" range="-1.57075 1.57075"/>
                <geom type="mesh" rgba="0.752941 0.752941 0.752941 1" mesh="shoulder_roll_link_l"/>
                <body name="elbow_pitch_link_l" pos="0.1146 0.005 0.005" quat="0.707107 -0.707107 0 0">
                  <inertial pos="0.0217884 0 0.0003604" quat="0.499291 0.500708 0.500708 0.499291" mass="0.0524404" diaginertia="7.261e-05 7.10305e-05 7.52949e-06"/>
                  <joint name="elbow_pitch_l" pos="0 0 0" axis="0 0 1" limited="true" range="-1.57075 1.57075"/>
                  <geom type="mesh" rgba="0.752941 0.752941 0.752941 1" mesh="elbow_pitch_link_l"/>
                </body>
              </body>
            </body>

          <!-- RIGHT ARM -->
          <body name="shoulder_pitch_link_r" pos="0.029216 -0.12375 0.152985" quat="0.5 0.5 -0.5 0.5">
              <inertial pos="0 -0.00038323 -0.0141368" quat="0.999984 0.0057278 0 0" mass="0.0493169" diaginertia="2.507e-05 2.40321e-05 8.31794e-06"/>
              <joint name="shoulder_pitch_r" pos="0 0 0" axis="0 0 1" limited="true" range="-1.57075 1.57075"/>
              <geom type="mesh" rgba="0.752941 0.752941 0.752941 1" mesh="shoulder_pitch_link_r"/>
              <body name="shoulder_roll_link_r" quat="0.5 0.5 -0.5 0.5">
                <inertial pos="0.0570939 -0.00419463 0.00093738" quat="-0.205082 0.694437 -0.169487 0.66856" mass="0.024" diaginertia="0.000126403 0.000125807 7.29e-06"/>
                <joint name="shoulder_roll_r" pos="0 0 0" axis="0 0 1" limited="true" range="-1.57075 1.57075"/>
                <geom type="mesh" rgba="0.752941 0.752941 0.752941 1" mesh="shoulder_roll_link_r"/>
                <body name="elbow_pitch_link_r" pos="0.1146 -0.005 0.005" quat="0.707107 0.707107 0 0">
                  <inertial pos="0.0217884 0 0.0003604" quat="0.499291 0.500708 0.500708 0.499291" mass="0.0524404" diaginertia="7.261e-05 7.10305e-05 7.52949e-06"/>
                  <joint name="elbow_pitch_r" pos="0 0 0" axis="0 0 1" limited="true" range="-1.57075 1.57075"/>
                  <geom type="mesh" rgba="0.752941 0.752941 0.752941 1" mesh="elbow_pitch_link_r"/>
                </body>
              </body>
            </body>
        </body>
    </worldbody>

    <actuator>
      <motor name="hip_yaw_l_act" ctrllimited="false" gear="1 0 0 0 0 0" joint="hip_yaw_l"/>
      <motor name="hip_roll_l_act" ctrllimited="false" gear="1 0 0 0 0 0" joint="hip_roll_l"/>
      <motor name="hip_pitch_l_act" ctrllimited="false" gear="1 0 0 0 0 0" joint="hip_pitch_l"/>
      <motor name="knee_pitch_l_act" ctrllimited="false" gear="1 0 0 0 0 0" joint="knee_pitch_l"/>
      <motor name="ankle_pitch_l_act" ctrllimited="false" gear="1 0 0 0 0 0" joint="ankle_pitch_l"/>
      <motor name="hip_yaw_r_act" ctrllimited="false" gear="1 0 0 0 0 0" joint="hip_yaw_r"/>
      <motor name="hip_roll_r_act" ctrllimited="false" gear="1 0 0 0 0 0" joint="hip_roll_r"/>
      <motor name="hip_pitch_r_act" ctrllimited="false" gear="1 0 0 0 0 0" joint="hip_pitch_r"/>
      <motor name="knee_pitch_r_act" ctrllimited="false" gear="1 0 0 0 0 0" joint="knee_pitch_r"/>
      <motor name="ankle_pitch_r_act" ctrllimited="false" gear="1 0 0 0 0 0" joint="ankle_pitch_r"/>
      <motor name="shoulder_pitch_l_act" ctrllimited="false" gear="1 0 0 0 0 0" joint="shoulder_pitch_l"/>
      <motor name="shoulder_roll_l_act" ctrllimited="false" gear="1 0 0 0 0 0" joint="shoulder_roll_l"/>
      <motor name="elbow_pitch_l_act" ctrllimited="false" gear="1 0 0 0 0 0" joint="elbow_pitch_l"/>
      <motor name="shoulder_pitch_r_act" ctrllimited="false" gear="1 0 0 0 0 0" joint="shoulder_pitch_r"/>
      <motor name="shoulder_roll_r_act" ctrllimited="false" gear="1 0 0 0 0 0" joint="shoulder_roll_r"/>
      <motor name="elbow_pitch_r_act" ctrllimited="false" gear="1 0 0 0 0 0" joint="elbow_pitch_r"/>
    </actuator>

    <!-- <key qpos='-0.0333572 0.000984914 0.438839 0.999816 0.00108816 0.019147 7.14565e-06 0.000671396 -3.42944e-05 0.4713 -0.9426 0.43988 0.000355333 -1.25085e-08 0.4713 -0.9426 0.43988 0.369773 -1.2194 -0.737021 -0.38312 1.22772 0.710698'/> -->
</mujoco>