<mujoco model="bruce_op">
  <compiler angle="radian" meshdir="meshes" autolimits="false" inertiafromgeom="false"/>

  <option timestep="0.001" gravity="0 0 -9.81" tolerance="1e-05" cone="elliptic" jacobian="dense" solver="Newton"  noslip_iterations="10" integrator="Euler" iterations="30" impratio="10.0"/> 
  <option>
    <flag override="enable" gravity="enable"/>
  </option>

  <asset>
      <mesh name="base_link" file="base_link.STL"/>
      <mesh name="ankle_pitch_link_l" file="ankle_pitch_link_l.stl"/>
      <mesh name="ankle_pitch_link_r" file="ankle_pitch_link_r.stl"/>
      <mesh name="elbow_pitch_link_l" file="elbow_pitch_link_l.stl"/>
      <mesh name="elbow_pitch_link_r" file="elbow_pitch_link_r.stl"/>
      <mesh name="hip_pitch_link_l" file="hip_pitch_link_l.stl"/>
      <mesh name="hip_pitch_link_r" file="hip_pitch_link_r.stl"/>
      <mesh name="hip_roll_link_l" file="hip_roll_link_l.stl"/>
      <mesh name="hip_roll_link_r" file="hip_roll_link_r.stl"/>
      <mesh name="hip_yaw_link_l" file="hip_yaw_link_l.stl"/>
      <mesh name="hip_yaw_link_r" file="hip_yaw_link_r.stl"/>
      <mesh name="knee_pitch_link_l" file="knee_pitch_link_l.stl"/>
      <mesh name="knee_pitch_link_r" file="knee_pitch_link_r.stl"/>
      <mesh name="shoulder_pitch_link_l" file="shoulder_pitch_link_l.stl"/>
      <mesh name="shoulder_pitch_link_r" file="shoulder_pitch_link_r.stl"/>
      <mesh name="shoulder_roll_link_l" file="shoulder_roll_link_l.stl"/>
      <mesh name="shoulder_roll_link_r" file="shoulder_roll_link_r.stl"/>
      
      <texture name="texplane" type="2d" builtin="checker" width="512" height="512" rgb1="0.1 0.2 0.3" rgb2="0.5 0.6 0.7" mark="edge" markrgb="1 1 1" />
      <material name="MatLink"  reflectance="0.5" specular="1" shininess="0.3" rgba="0.5 0.5 0.5 1"/>
      <material name="MatPlane" texture="texplane" reflectance="0" texrepeat="1 1" texuniform="true"/>
  </asset>

  <default>
    <!-- <geom contype="1" conaffinity="1" condim="3" material="MatLink"/> -->
    <joint limited="false" damping="2" armature="0.1" stiffness="0" frictionloss="0.2"/>
    <!-- <joint limited="false" damping="0.5" armature="0.1" stiffness="0" frictionloss="0.2"/> -->
    <motor gear="1 0 0 0 0 0" ctrllimited="false" ctrlrange="-100 100"/>
  </default>

  <!-- Ref:https://github.com/google-deepmind/mujoco_menagerie/blob/main/robotis_op3/op3.xml -->
  <!-- <default>
    <mesh scale="0.001 0.001 0.001"/>
    <geom type="mesh" solref=".004 1"/>
    <joint damping="1.084" armature="0.045" frictionloss="0.03"/>
    <site group="5" type="sphere"/>
    <position kp="21.1" ctrlrange="-3.141592 3.141592" forcerange="-5 5"/>
    <default class="collision">
      <geom group="3"/>
      <default class="foot">
        <geom mass="0" type="box"/>
      </default>
    </default>
    <default class="visual">
      <geom material="black" contype="0" conaffinity="0" group="2"/>
    </default>
  </default> -->

  <visual>
    <global fovy="45" linewidth="2" glow="0.3"/>
    <quality shadowsize="4096" numslices="48"/>
    <map stiffness="50" stiffnessrot="100"/>
    <scale forcewidth="0.075" contactwidth="0.2" contactheight="0.1" connect="0.1" com="0.2" jointlength="0.25" jointwidth="0.05"
           actuatorlength="0.5" actuatorwidth="0.3" framelength="1" framewidth="0.03"/>
    <rgba haze="0.6 0.8 0.9 1" force="1 0 0 0.5" com="0 0 1 1"/>
  </visual>

  <worldbody>
      <light name="spotlight" mode="targetbodycom" target="base_link" pos="10 -10 10" diffuse="1.0 1.0 1.0" specular="0.0 0.0 0.0" castshadow="false"/>
      <geom name="Ground" type="plane" pos="0 0 0" material="MatPlane" size="0 0 1" condim="3"/>
      
      <body name="base_link" pos="0 0 0.47">
        <freejoint/>
        <inertial pos="0.02259605 -0.00011305 0.06140054" mass="1.31688922" fullinertia="0.0133543 0.01023631 0.005471 -3.36E-06 0.00182725 -1.163E-05"/>
        <geom name="base_link" type="mesh" mesh="base_link" rgba="0.752941176 0.752941176 0.752941176 1"/>

        <!-- RIGHT LEG -->
        <body name="hip_yaw_link_r" pos="0.029216 -0.0758557 -0.039765" quat="0.707107 0 0 -0.707107">
          <inertial pos="2.71e-06 -0.00024824 0.00522427" mass="0.637563" fullinertia="0.000485406 0.00161689 0.00152129 1.12E-06 1.74E-06 -7.02E-06"/>
          <joint name="hip_yaw_r" pos="0 0 0" axis="0 0 1" limited="true" range="-0.785375 0.785375"/>
          <geom type="mesh" rgba="0.752941 0.752941 0.752941 1" mesh="hip_yaw_link_r" contype="0" conaffinity="0"/>
          <body name="hip_roll_link_r" quat="0.5 -0.5 0.5 0.5">
            <inertial pos="-1.51e-07 0 6.88e-06" mass="0.05" fullinertia="1e-05 1e-05 1e-05 1.00E-20 1.00E-20 1.00E-20"/>
            <joint name="hip_roll_r" pos="0 0 0" axis="0 0 1" limited="true" range="-0.785375 0.785375"/>
            <geom type="mesh" rgba="0.752941 0.752941 0.752941 1" mesh="hip_roll_link_r" contype="0" conaffinity="0"/>
            <body name="hip_pitch_link_r" quat="0.707107 0.707107 0 0">
              <inertial pos="0.140714 -0.0086817 0.00167429" mass="0.72849" fullinertia="0.00050614 0.01792426 0.01819732 -0.00065644 0.00019343 1.68E-06"/>
              <joint name="hip_pitch_r" pos="0 0 0" axis="0 0 1" limited="true" range="-1.57075 1.57075"/>
              <geom type="mesh" rgba="0.752941 0.752941 0.752941 1" mesh="hip_pitch_link_r"/>
              <body name="knee_pitch_link_r" pos="0.204949 0 0">
                <inertial pos="0.0729308 0.0174645 0.00216432" mass="0.0956654" fullinertia="0.00010962 0.00101941 0.00108317 5.276E-05 1.568E-05 -6.68E-06"/>
                <joint name="knee_pitch_r" pos="0 0 0" axis="0 0 1" limited="true" range="-1.57075 1.57075"/>
                <geom type="mesh" rgba="0.752941 0.752941 0.752941 1" mesh="knee_pitch_link_r"/>
                <body name="ankle_pitch_link_r" pos="0.199881 0 0">
                  <inertial pos="0.0120775 0.0019746 0.00029511" mass="0.0276265" fullinertia="2.043E-05 6.2E-06 2.588E-05 2.87E-06 -3E-08 -2.4E-07"/>
                  <joint name="ankle_pitch_r" pos="0 0 0" axis="0 0 1" limited="true" range="-1.57075 1.57075"/>
                  <geom type="mesh" rgba="0.792157 0.819608 0.933333 1" mesh="ankle_pitch_link_r"/>
                  <site name="rfoot_sensor" type="sphere" pos="0 0 0" size="0.005" rgba="1 0 0 1"/>
                </body>
              </body>
            </body>
          </body>
        </body>
        <!-- LEFT LEG -->
        <body name="hip_yaw_link_l" pos="0.029216 0.0758557 -0.039765" quat="0.707107 0 0 -0.707107">
            <inertial pos="0 -0.00020849 0.00528032" mass="0.637386" fullinertia="0.0004852 0.0016181 0.00152105 0 -1.6E-07 -7.5E-06"/>
            <joint name="hip_yaw_l" pos="0 0 0" axis="0 0 1" limited="true" range="-0.785375 0.785375"/>
            <geom type="mesh" rgba="0.752941 0.752941 0.752941 1" mesh="hip_yaw_link_l" contype="0" conaffinity="0"/>
            <body name="hip_roll_link_l" quat="0.500001 -0.499999 0.500001 0.499999">
              <inertial pos="-1.51e-07 0 6.88e-06" mass="0.05" fullinertia="1e-05 1e-05 1e-05 1.00E-20 1.00E-20 1.00E-20"/>
              <joint name="hip_roll_l" pos="0 0 0" axis="0 0 1" limited="true" range="-0.785375 0.785375"/>
              <geom type="mesh" rgba="0.752941 0.752941 0.752941 1" mesh="hip_roll_link_l" contype="0" conaffinity="0"/>
              <body name="hip_pitch_link_l" quat="0.707107 0.707107 0 0">
                <inertial pos="0.142447 -0.00832054 0.00049317" mass="0.720628" fullinertia="0.00048935 0.01792901 0.01819268 -0.00066556 -0.0001932 3.2E-07"/>
                <joint name="hip_pitch_l" pos="0 0 0" axis="0 0 1" limited="true" range="-1.57075 1.57075"/>
                <geom type="mesh" rgba="0.752941 0.752941 0.752941 1" mesh="hip_pitch_link_l"/>
                <body name="knee_pitch_link_l" pos="0.204949 0 0">
                  <inertial pos="0.0730996 0.0178102 -0.00219767" mass="0.0952654" fullinertia="0.00010799 0.00101705 0.0010792 5.259E-05 -1.742E-05 6.07E-06"/>
                  <joint name="knee_pitch_l" pos="0 0 0" axis="0 0 1" limited="true" range="-1.57075 1.57075"/>
                  <geom type="mesh" rgba="0.752941 0.752941 0.752941 1" mesh="knee_pitch_link_l"/>
                  <body name="ankle_pitch_link_l" pos="0.199881 0 0">
                    <inertial pos="0.0123398 0.00253004 -0.00030441" mass="0.0274829" fullinertia="2.042E-05 6.27E-06 2.602E-05 2.91E-06 3E-08 2.4E-07"/>
                    <joint name="ankle_pitch_l" pos="0 0 0" axis="0 0 1" limited="true" range="-1.57075 1.57075"/>
                    <geom type="mesh" rgba="0.792157 0.819608 0.933333 1" mesh="ankle_pitch_link_l"/>
                    <site name="lfoot_sensor" type="sphere" pos="0 0 0" size="0.005" rgba="1 0 0 1"/>
                  </body>
                </body>
              </body>
            </body>
        </body>
        <!-- RIGHT ARM -->
        <body name="shoulder_pitch_link_r" pos="0.029216 -0.12375 0.152985" quat="0.5 0.5 -0.5 0.5">
            <inertial pos="0 -0.00038323 -0.0141368" mass="0.0493169" fullinertia="2.507E-05 2.403E-05 8.32E-06 0 0 1.8E-07"/>
            <joint name="shoulder_pitch_r" pos="0 0 0" axis="0 0 1" limited="true" range="-1.57075 1.57075"/>
            <geom type="mesh" rgba="0.752941 0.752941 0.752941 1" mesh="shoulder_pitch_link_r"/>
            <body name="shoulder_roll_link_r" quat="0.5 0.5 -0.5 0.5">
              <inertial pos="0.0570939 -0.00419463 0.00093738" mass="0.024" fullinertia="7.75E-06 0.00012556 0.00012619 -6.9E-06 2.62E-06 -1.1E-07"/>
              <joint name="shoulder_roll_r" pos="0 0 0" axis="0 0 1" limited="true" range="-1.57075 1.57075"/>
              <geom type="mesh" rgba="0.752941 0.752941 0.752941 1" mesh="shoulder_roll_link_r"/>
              <body name="elbow_pitch_link_r" pos="0.1146 -0.005 0.005" quat="0.707107 0.707107 0 0">
                <inertial pos="0.0217884 0 0.0003604" mass="0.0524404" fullinertia="7.53E-06 7.261E-05 7.103E-05 0 1.8E-07 0"/>
                <joint name="elbow_pitch_r" pos="0 0 0" axis="0 0 1" limited="true" range="-1.57075 1.57075"/>
                <geom type="mesh" rgba="0.752941 0.752941 0.752941 1" mesh="elbow_pitch_link_r"/>
              </body>
            </body>
        </body>
        <!-- LEFT ARM -->
        <body name="shoulder_pitch_link_l" pos="0.029216 0.12375 0.152985" quat="0.5 -0.5 0.5 0.5">
          <inertial pos="0 0.00038323 -0.0141368" mass="0.0493169" fullinertia="2.507E-05 2.403E-05 8.32E-06 0 0 -1.8E-07"/>
          <joint name="shoulder_pitch_l" pos="0 0 0" axis="0 0 1" limited="true" range="-1.57075 1.57075"/>
          <geom type="mesh" rgba="0.752941 0.752941 0.752941 1" mesh="shoulder_pitch_link_l"/>
          <body name="shoulder_roll_link_l" quat="0.5 0.5 -0.5 0.5">
            <inertial pos="0.0570939 0.00419463 0.00094155" mass="0.0313652" fullinertia="1.013E-05 0.00016409 0.00016491 9.02E-06 3.42E-06 1.5E-07"/>
            <joint name="shoulder_roll_l" pos="0 0 0" axis="0 0 1" limited="true" range="-1.57075 1.57075"/>
            <geom type="mesh" rgba="0.752941 0.752941 0.752941 1" mesh="shoulder_roll_link_l"/>
            <body name="elbow_pitch_link_l" pos="0.1146 0.005 0.005" quat="0.707107 -0.707107 0 0">
              <inertial pos="0.0217884 0 0.0003604" mass="0.0524404" fullinertia="7.53E-06 7.261E-05 7.103E-05 0 1.8E-07 0"/>
              <joint name="elbow_pitch_l" pos="0 0 0" axis="0 0 1" limited="true" range="-1.57075 1.57075"/>
              <geom type="mesh" rgba="0.752941 0.752941 0.752941 1" mesh="elbow_pitch_link_l"/>
            </body>
          </body>
        </body>
      </body>
  </worldbody>

  <actuator>
    <motor name="hip_yaw_r_act" ctrllimited="false" gear="1 0 0 0 0 0" joint="hip_yaw_r"/>
    <motor name="hip_roll_r_act" ctrllimited="false" gear="1 0 0 0 0 0" joint="hip_roll_r"/>
    <motor name="hip_pitch_r_act" ctrllimited="false" gear="1 0 0 0 0 0" joint="hip_pitch_r"/>
    <motor name="knee_pitch_r_act" ctrllimited="false" gear="1 0 0 0 0 0" joint="knee_pitch_r"/>
    <motor name="ankle_pitch_r_act" ctrllimited="false" gear="1 0 0 0 0 0" joint="ankle_pitch_r"/>
    <motor name="hip_yaw_l_act" ctrllimited="false" gear="1 0 0 0 0 0" joint="hip_yaw_l"/>
    <motor name="hip_roll_l_act" ctrllimited="false" gear="1 0 0 0 0 0" joint="hip_roll_l"/>
    <motor name="hip_pitch_l_act" ctrllimited="false" gear="1 0 0 0 0 0" joint="hip_pitch_l"/>
    <motor name="knee_pitch_l_act" ctrllimited="false" gear="1 0 0 0 0 0" joint="knee_pitch_l"/>
    <motor name="ankle_pitch_l_act" ctrllimited="false" gear="1 0 0 0 0 0" joint="ankle_pitch_l"/>
    <motor name="shoulder_pitch_r_act" ctrllimited="false" gear="1 0 0 0 0 0" joint="shoulder_pitch_r"/>
    <motor name="shoulder_roll_r_act" ctrllimited="false" gear="1 0 0 0 0 0" joint="shoulder_roll_r"/>
    <motor name="elbow_pitch_r_act" ctrllimited="false" gear="1 0 0 0 0 0" joint="elbow_pitch_r"/>
    <motor name="shoulder_pitch_l_act" ctrllimited="false" gear="1 0 0 0 0 0" joint="shoulder_pitch_l"/>
    <motor name="shoulder_roll_l_act" ctrllimited="false" gear="1 0 0 0 0 0" joint="shoulder_roll_l"/>
    <motor name="elbow_pitch_l_act" ctrllimited="false" gear="1 0 0 0 0 0" joint="elbow_pitch_l"/>
  </actuator>

  <!-- <key qpos='-0.0333572 0.000984914 0.438839 0.999816 0.00108816 0.019147 7.14565e-06 0.000671396 -3.42944e-05 0.4713 -0.9426 0.43988 0.000355333 -1.25085e-08 0.4713 -0.9426 0.43988 0.369773 -1.2194 -0.737021 -0.38312 1.22772 0.710698'/> -->
</mujoco>